Workbook

Sheet Sheet1
B1: Alkem Laboratories Ltd
B2: Historical Financial Information
B4: Income Statement | H4: 2021 | I4: =H4+1 -> 2022 | J4: =I4+1 -> 2023 | K4: =J4+1 -> 2024 | L4: =K4+1 -> 2025
C5: Income
C6: (a) Revenue from operations | H6: 88650.1 | I6: 106341.9 | J6: 115992.6 | K6: 126675.8 | L6: 129645.2
C7: (b) Other income | H7: 2332.1 | I7: 1626.5 | J7: 2160.8 | K7: 3108.4 | L7: 4937.4
C8: Total income | H8: =SUM(H6:H7) -> 90982.2 | I8: =SUM(I6:I7) -> 107968.4 | J8: =SUM(J6:J7) -> 118153.4 | K8: =SUM(K6:K7) -> 129784.2 | L8: 134582.6
K9: 32945.9 | L9: 34403.7
C10: Expenses
C11: Cost of materials consumed | H11: 23945.4 | I11: 32260.6 | J11: 30569.2 | K11: 32945.9 | L11: 34403.7
C12: Purchases of stock-in-trade | H12: 14377.6 | I12: 14897.1 | J12: 13875.5 | K12: 16288.7 | L12: 15140.2
C13: Changes in inventories of finished goods, work-in-progress and stock-in-trade | H13: -3338.4 | I13: -5354.8 | J13: 4623.7 | K13: 141.2 | L13: -1901.3
C14: Employee benefits expense | H14: 16210.3 | I14: 19627.1 | J14: 21313.5 | K14: 22010.1 | L14: 24539.2
C15: Finance costs | H15: 589.2 | I15: 523.7 | J15: 1073.6 | K15: 1124.1 | L15: 1217
C16: Depreciation and amortisation expense | H16: 2745.8 | I16: 3039.6 | J16: 3104.2 | K16: 2993 | L16: 3571.6
C17: Other expenses | H17: 18031.3 | I17: 24382.7 | J17: 29516.2 | K17: 32835 | L17: 32341.9
C18: Total expenses | H18: =SUM(H11:H17) -> 72561.2 | I18: =SUM(I11:I17) -> 89376 | J18: =SUM(J11:J17) -> 104075.9 | K18: =SUM(K11:K17) -> 108338 | L18: =SUM(L11:L17) -> 109312.3
C20: Profit before exceptional items and tax (1) - (2) | H20: 18421 | I20: 18592.4 | J20: 14077.5 | K20: 21446.2 | L20: 25270.3
C21: Exceptional items | H21: 0 | I21: -149.6 | J21: -1029.8 | K21: -1214.9 | L21: 0
C22: Profit before tax (3) + (4) | H22: =SUM(H20:H21) -> 18421 | I22: =SUM(I20:I21) -> 18442.8 | J22: =SUM(J20:J21) -> 13047.7 | K22: =SUM(K20:K21) -> 20231.3 | L22: =SUM(L20:L21) -> 25270.3
C23: Tax expense
C24: (a) Current tax | H24: 3965.3 | I24: 3619.8 | J24: 2739 | K24: 4222.8 | L24: 5236
C25: (b) Deferred tax charge/(credit) (net) | H25: -1722 | I25: -1980.2 | J25: 240.6 | K25: -2106.1 | L25: -2125.7
C26: Total tax expenses (a + b) | H26: =SUM(H24:H25) -> 2243.3 | I26: =SUM(I24:I25) -> 1639.6 | J26: =SUM(J24:J25) -> 2979.6 | K26: =SUM(K24:K25) -> 2116.7 | L26: =SUM(L24:L25) -> 3110.3
C27: Profit for the year (5) - (6) | H27: =H22-H26 -> 16177.7 | I27: =I22-I26 -> 16803.2 | J27: =J22-J26 -> 10068.1 | K27: =K22-K26 -> 18114.6 | L27: =L22-L26 -> 22160
B29: Balance Sheet
B30: Particulars | H30: 2021 | I30: =H30+1 -> 2022 | J30: =I30+1 -> 2023 | K30: =J30+1 -> 2024 | L30: =K30+1 -> 2025
B31: ASSETS
B32: Non-current assets
B33: (a) Property, plant and equipment | H33: 22339.3 | I33: 22871 | J33: 20654 | K33: 21614.6 | L33: 20639.3
B34: (b) Right of use assets | H34: 0 | I34: 1393.5 | J34: 1378.5 | K34: 2471.7 | L34: 3222.2
B35: (c) Capital work in progress | H35: 3932.8 | I35: 3394.8 | J35: 3102.7 | K35: 1484 | L35: 4765.5
B36: (d) Goodwill | H36: 3953.9 | I36: 4030.9 | J36: 4131.7 | K36: 4167.4 | L36: 4231.1
B37: (e) Other intangible assets | H37: 1636.6 | I37: 721.9 | J37: 664.1 | K37: 474.1 | L37: 430.5
B38: (f) Intangible assets under development | H38: 0 | J38: 129.7 | K38: 101.7 | L38: 715.2
B39: (g) Financial assets
C40: (i) Investment in associate | H40: 1539.5 | I40: 2316.7 | J40: 3046.1 | K40: 0 | L40: 323.8
C41: (ii) Other investments | H41: 80.2 | I41: 80.2 | J41: 80.2 | K41: 3348 | L41: 9108.6
C42: (iii) Other financial assets | H42: 607.9 | I42: 7106.7 | J42: 2952.5 | K42: 1202.2 | L42: 4753.6
B43: (h) Deferred tax assets (net) | H43: 11079.1 | I43: 13092.6 | J43: 13025 | K43: 15148.3 | L43: 17382.5
...

Sheet Model
A1: =Sheet1!B1 -> Alkem Laboratories Ltd | H1: Historical Period | M1: Estimate Period
B2: Financial Statements & DCF Analysis | H2: =Sheet1!H4 -> 2021 | I2: =Sheet1!I4 -> 2022 | J2: =Sheet1!J4 -> 2023 | K2: =Sheet1!K4 -> 2024 | L2: =Sheet1!L4 -> 2025 | M2: =L2+1 -> 2026 | N2: =M2+1 -> 2027 | O2: =N2+1 -> 2028 | P2: =O2+1 -> 2029 | Q2: =P2+1 -> 2030
A4: INCOME STATEMENT
B5: INCOME
C6: Revenue | F6: ₹ MM | H6: =Sheet1!H6 -> 88650.1 | I6: =Sheet1!I6 -> 106341.9 | J6: =Sheet1!J6 -> 115992.6 | K6: =Sheet1!K6 -> 126675.8 | L6: =Sheet1!L6 -> 129645.2 | M6: =L6*(1+M107) -> 142799.78 | N6: =M6*(1+N107) -> 154391.23 | O6: =N6*(1+O107) -> 164417.12 | P6: =O6*(1+P107) -> 172958.68 | Q6: =P6*(1+Q107) -> 180146.93
C7: Cost of Good Sold (COGS) | F7: ₹ MM | H7: =-SUM(Sheet1!H11:H13) -> -34984.6 | I7: =-SUM(Sheet1!I11:I13) -> -41802.9 | J7: =-SUM(Sheet1!J11:J13) -> -49068.4 | K7: =-SUM(Sheet1!K11:K13) -> -49375.8 | L7: =-SUM(Sheet1!L11:L13) -> -47642.6 | M7: =-M6*M108 -> -56206.897 | N7: =-N6*N108 -> -60729.59 | O7: =-O6*O108 -> -64694.113 | P7: =-P6*P108 -> -66771.581 | Q7: =-Q6*Q108 -> -69713.035
C8: Gross Profit | F8: ₹ MM | H8: =SUM(H6:H7) -> 53665.5 | I8: =SUM(I6:I7) -> 64539 | J8: =SUM(J6:J7) -> 66924.2 | K8: =SUM(K6:K7) -> 77300 | L8: =SUM(L6:L7) -> 82002.6 | M8: =SUM(M6:M7) -> 86592.878 | N8: =SUM(N6:N7) -> 93661.639 | O8: =SUM(O6:O7) -> 99723.007 | ... Q8: =SUM(Q6:Q7) -> 110433.89
B9: EXPENSES
C10: Salaries and benefits | F10: ₹ MM | H10: =-Sheet1!H14 -> -16210.3 | I10: =-Sheet1!I14 -> -19627.1 | J10: =-Sheet1!J14 -> -21313.5 | K10: =-Sheet1!K14 -> -22010.1 | L10: =-Sheet1!L14 -> -24539.2 | M10: =-M6*M109 -> -26109.596 | N10: =-N6*N109 -> -28228.347 | O10: =-O6*O109 -> -29990.524 | P10: =-P6*P109 -> -31509.101 | Q10: =-Q6*Q109 -> -33208.368
C11: Other SG&A Expenses | F11: ₹ MM | H11: =-Sheet1!H17 -> -18031.3 | I11: =-Sheet1!I17 -> -24382.7 | J11: =-Sheet1!J17 -> -29516.2 | K11: =-Sheet1!K17 -> -32835 | L11: =-Sheet1!L17 -> -32341.9 | M11: =-M6*M110 -> -34152.576 | N11: =-N6*N110 -> -38305.307 | O11: =-O6*O110 -> -41198.82 | P11: =-P6*P110 -> -43064.084 | Q11: =-Q6*Q110 -> -44465.18
C12: EBITDA | F12: ₹ MM | H12: =SUM(H8:H11) -> 19423.9 | I12: =SUM(I8:I11) -> 20529.2 | J12: =SUM(J8:J11) -> 16094.5 | K12: =SUM(K8:K11) -> 22454.9 | L12: =SUM(L8:L11) -> 25121.5 | M12: =SUM(M8:M11) -> 26330.706 | N12: =SUM(N8:N11) -> 27127.985 | O12: =SUM(O8:O11) -> 28533.663 | ... Q12: =SUM(Q8:Q11) -> 32760.343
C13: =Sheet1!C16 -> Depreciation and amortisation expense | F13: ₹ MM | H13: =-Sheet1!H16 -> -2745.8 | I13: =-Sheet1!I16 -> -3039.6 | J13: =-Sheet1!J16 -> -3104.2 | K13: =-Sheet1!K16 -> -2993 | L13: =-Sheet1!L16 -> -3571.6 | M13: =M95 -> -3500.672 | N13: =N95 -> -3407.6778 | O13: =O95 -> -3321.6489 | P13: =P95 -> -3182.5565 | Q13: =Q95 -> -2984.8573
C14: EBIT | F14: ₹ MM | H14: =SUM(H12:H13) -> 16678.1 | I14: =SUM(I12:I13) -> 17489.6 | J14: =SUM(J12:J13) -> 12990.3 | K14: =SUM(K12:K13) -> 19461.9 | L14: =SUM(L12:L13) -> 21549.9 | M14: =SUM(M12:M13) -> 22830.034 | N14: =SUM(N12:N13) -> 23720.307 | O14: =SUM(O12:O13) -> 25212.014 | ... Q14: =SUM(Q12:Q13) -> 29775.486
C15: Interest | F15: ₹ MM | H15: =-Sheet1!H15 -> -589.2 | I15: =-Sheet1!I15 -> -523.7 | J15: =-Sheet1!J15 -> -1073.6 | K15: =-Sheet1!K15 -> -1124.1 | L15: =-Sheet1!L15 -> -1217 | M15: =M102 -> -813.85305 | N15: =N102 -> -813.85305 | O15: =O102 -> -916.42549 | P15: =P102 -> -980.98052 | Q15: =Q102 -> -932.23697
C16: Other Income (Expense) | F16: ₹ MM | H16: =Sheet1!H7+Sheet1!H21 -> 2332.1 | I16: =Sheet1!I7+Sheet1!I21 -> 1476.9 | J16: =Sheet1!J7+Sheet1!J21 -> 1131 | K16: =Sheet1!K7+Sheet1!K21 -> 1893.5 | L16: =Sheet1!L7+Sheet1!L21 -> 4937.4 | M16: =M6*M113 -> 2941.0238 | N16: =N6*N113 -> 2959.309 | O16: =O6*O113 -> 3427.1764 | P16: =P6*P113 -> 4012.4072 | Q16: =Q6*Q113 -> 4444.737
C17: Earnings before Tax | F17: ₹ MM | H17: =SUM(H14:H16) -> 18421 | I17: =SUM(I14:I16) -> 18442.8 | J17: =SUM(J14:J16) -> 13047.7 | K17: =SUM(K14:K16) -> 20231.3 | L17: =SUM(L14:L16) -> 25270.3 | M17: =SUM(M14:M16) -> 24957.205 | N17: =SUM(N14:N16) -> 25865.763 | O17: =SUM(O14:O16) -> 27722.765 | ... Q17: =SUM(Q14:Q16) -> 33287.986
C18: Tax | F18: ₹ MM | H18: =-Sheet1!H26 -> -2243.3 | I18: =-Sheet1!I26 -> -1639.6 | J18: =-Sheet1!J26 -> -2979.6 | K18: =-Sheet1!K26 -> -2116.7 | L18: =-Sheet1!L26 -> -3110.3 | M18: =-M17*M114 -> -3328.042 | N18: =-N17*N114 -> -3524.0178 | O18: =-O17*O114 -> -4085.0763 | P18: =-P17*P114 -> -3911.6014 | Q18: =-Q17*Q114 -> -4494.1138
C19: Net Earnings | F19: ₹ MM | H19: =SUM(H17:H18) -> 16177.7 | I19: =SUM(I17:I18) -> 16803.2 | J19: =SUM(J17:J18) -> 10068.1 | K19: =SUM(K17:K18) -> 18114.6 | L19: =SUM(L17:L18) -> 22160 | M19: =SUM(M17:M18) -> 21629.163 | N19: =SUM(N17:N18) -> 22341.745 | O19: =SUM(O17:O18) -> 23637.689 | ... Q19: =SUM(Q17:Q18) -> 28793.872
A21: Balance Sheet
B23: Asset
C24: Current Asset
D25: Cash | F25: ₹ MM | H25: =Sheet1!H53 -> 1742.2 | I25: =Sheet1!I53 -> 2321.8 | J25: =Sheet1!J53 -> 2738 | K25: =Sheet1!K53 -> 4550.7 | L25: =Sheet1!L53 -> 3041.4 | M25: =M81 -> 7318.6705 | N25: =N81 -> 20967.534 | O25: =O81 -> 37288.196 | P25: =P81 -> 56837.872 | Q25: =Q81 -> 62338.946
D26: Bank Deposit | F26: ₹ MM | H26: =Sheet1!H54 -> 18162.3 | I26: =Sheet1!I54 -> 23464 | J26: =Sheet1!J54 -> 23430.9 | K26: =Sheet1!K54 -> 11242.8 | L26: =Sheet1!L54 -> 12589.4 | M26: =L26 -> 12589.4 | N26: =M26 -> 12589.4 | O26: =N26 -> 12589.4 | P26: =O26 -> 12589.4 | Q26: =P26 -> 12589.4
D27: Account Receivable | F27: ₹ MM | H27: =Sheet1!H52 -> 16072.1 | I27: =Sheet1!I52 -> 18846 | J27: =Sheet1!J52 -> 21321.8 | K27: =Sheet1!K52 -> 22528.1 | L27: =Sheet1!L52 -> 24662.5 | M27: =M6*M116/365 -> 26001.287 | N27: =N6*N116/365 -> 28142.144 | O27: =O6*O116/365 -> 30169.465 | P27: =P6*P116/365 -> 31670.1 | Q27: =Q6*Q116/365 -> 33240.91
D28: Inventory | F28: ₹ MM | H28: =Sheet1!H49 -> 23124.4 | I28: =Sheet1!I49 -> 30055.3 | J28: =Sheet1!J49 -> 26075.3 | K28: =Sheet1!K49 -> 26611.8 | L28: =Sheet1!L49 -> 29224.1 | M28: =-M7*M117/365 -> 34440.65 | N28: =-N7*N117/365 -> 36479.517 | O28: =-O7*O117/365 -> 37142.864 | P28: =-P7*P117/365 -> 39492.095 | Q28: =-Q7*Q117/365 -> 41844.703
D29: Other Current Asset | F29: ₹ MM | H29: =Sheet1!H57 -> 5550.1 | I29: =Sheet1!I57 -> 6322.8 | J29: =Sheet1!J57 -> 7360.9 | K29: =Sheet1!K57 -> 8299.8 | L29: =Sheet1!L57 -> 8326.7 | M29: =L29 -> 8326.7 | N29: =M29 -> 8326.7 | O29: =N29 -> 8326.7 | P29: =O29 -> 8326.7 | Q29: =P29 -> 8326.7
C31: Non-Current Asset
D32: Property & Equipment | F32: ₹ MM | H32: =Sheet1!H33+Sheet1!H34+Sheet1!H35+Sheet1!H37+Sheet1!H38 -> 27908.7 | I32: =Sheet1!I33+Sheet1!I34+Sheet1!I35+Sheet1!I37+Sheet1!I38 -> 28381.2 | J32: =Sheet1!J33+Sheet1!J34+Sheet1!J35+Sheet1!J37+Sheet1!J38 -> 25929 | K32: =Sheet1!K33+Sheet1!K34+Sheet1!K35+Sheet1!K37+Sheet1!K38 -> 26146.1 | L32: =Sheet1!L33+Sheet1!L34+Sheet1!L35+Sheet1!L37+Sheet1!L38 -> 29772.7 | M32: =M96 -> 28981.798 | N32: =N96 -> 27738.926 | O32: =O96 -> 26129.788 | P32: =P96 -> 24291.407 | Q32: =Q96 -> 22355.239
D33: Goodwill | F33: ₹ MM | H33: =Sheet1!H36 -> 3953.9 | I33: =Sheet1!I36 -> 4030.9 | J33: =Sheet1!J36 -> 4131.7 | K33: =Sheet1!K36 -> 4167.4 | L33: =Sheet1!L36 -> 4231.1 | M33: =L33 -> 4231.1 | N33: =M33 -> 4231.1 | O33: =N33 -> 4231.1 | P33: =O33 -> 4231.1 | Q33: =P33 -> 4231.1
D34: Financial Asset | F34: ₹ MM | H34: =Sheet1!H40+Sheet1!H41+Sheet1!H42+Sheet1!H51+Sheet1!H55+Sheet1!H56+Sheet1!H59 -> 6864.7 | I34: =Sheet1!I40+Sheet1!I41+Sheet1!I42+Sheet1!I51+Sheet1!I55+Sheet1!I56+Sheet1!I59 -> 12848 | J34: =Sheet1!J40+Sheet1!J41+Sheet1!J42+Sheet1!J51+Sheet1!J55+Sheet1!J56+Sheet1!J59 -> 12448.7 | K34: =Sheet1!K40+Sheet1!K41+Sheet1!K42+Sheet1!K51+Sheet1!K55+Sheet1!K56+Sheet1!K59 -> 35432.8 | L34: =Sheet1!L40+Sheet1!L41+Sheet1!L42+Sheet1!L51+Sheet1!L55+Sheet1!L56+Sheet1!L59 -> 45800.1 | M34: =L34 -> 45800.1 | N34: =M34 -> 45800.1 | O34: =N34 -> 45800.1 | P34: =O34 -> 45800.1 | Q34: =P34 -> 45800.1
D35: Other Non-Current Asset | F35: ₹ MM | H35: =SUM(Sheet1!H43:H45) -> 11814.2 | I35: =SUM(Sheet1!I43:I45) -> 14421.9 | J35: =SUM(Sheet1!J43:J45) -> 14130 | K35: =SUM(Sheet1!K43:K45) -> 16769.5 | L35: =SUM(Sheet1!L43:L45) -> 19263 | M35: =L35 -> 19263 | N35: =M35 -> 19263 | O35: =N35 -> 19263 | P35: =O35 -> 19263 | Q35: =P35 -> 19263
D36: Total Assets | F36: ₹ MM | H36: =SUM(H25:H35) -> 115192.6 | I36: =SUM(I25:I35) -> 140691.9 | J36: =SUM(J25:J35) -> 137566.3 | K36: =SUM(K25:K35) -> 155749 | L36: =SUM(L25:L35) -> 176911 | M36: =SUM(M25:M35) -> 186952.71 | N36: =SUM(N25:N35) -> 203538.42 | O36: =SUM(O25:O35) -> 220940.61 | ... Q36: =SUM(Q25:Q35) -> 249990.1
B38: Liabilities
C39: Current liabilities
D40: Accounts Paybale | F40: ₹ MM | H40: =Sheet1!H86+Sheet1!H87 -> 10694.1 | I40: =Sheet1!I86+Sheet1!I87 -> 11733.8 | J40: =Sheet1!J86+Sheet1!J87 -> 11650.3 | K40: =Sheet1!K86+Sheet1!K87 -> 17481.2 | L40: =Sheet1!L86+Sheet1!L87 -> 18393.5 | M40: =-M7*M118/365 -> 17580.617 | N40: =-N7*N118/365 -> 19103.095 | O40: =-O7*O118/365 -> 20869.192 | P40: =-P7*P118/365 -> 22826.872 | Q40: =-Q7*Q118/365 -> 23284.136
D41: Other Current Liabilities | F41: ₹ MM | H41: =Sheet1!H88+Sheet1!H89+Sheet1!H90+Sheet1!H91 -> 8403 | I41: =Sheet1!I88+Sheet1!I89+Sheet1!I90+Sheet1!I91 -> 10396.2 | J41: =Sheet1!J88+Sheet1!J89+Sheet1!J90+Sheet1!J91 -> 12157.7 | K41: =Sheet1!K88+Sheet1!K89+Sheet1!K90+Sheet1!K91 -> 10572.8 | L41: =Sheet1!L88+Sheet1!L89+Sheet1!L90+Sheet1!L91 -> 13167.7 | M41: =L41 -> 13167.7 | N41: =M41 -> 13167.7 | O41: =N41 -> 13167.7 | P41: =O41 -> 13167.7
C42: Non-Current Liabilities
D43: Debt | F43: ₹ MM | H43: =Sheet1!H74+Sheet1!H75+Sheet1!H83+Sheet1!H84 -> 17919.8 | I43: =Sheet1!I74+Sheet1!I75+Sheet1!I83+Sheet1!I84 -> 26681.9 | J43: =Sheet1!J74+Sheet1!J75+Sheet1!J83+Sheet1!J84 -> 13966.8 | K43: =Sheet1!K74+Sheet1!K75+Sheet1!K83+Sheet1!K84 -> 14184.1 | L43: =Sheet1!L74+Sheet1!L75+Sheet1!L83+Sheet1!L84 -> 13809 | M43: =M101 -> 13809 | N43: =N101 -> 13809 | O43: =O101 -> 13809 | P43: =P101 -> 13809 | Q43: =Q101 -> 13809
D44: Other Non-Current Liabilities | F44: ₹ MM | H44: =SUM(Sheet1!H76:H78) -> 2595.6 | I44: =SUM(Sheet1!I76:I78) -> 3406.7 | J44: =SUM(Sheet1!J76:J78) -> 5441.7 | K44: =SUM(Sheet1!K76:K78) -> 6366.9 | L44: =SUM(Sheet1!L76:L78) -> 7141.6 | M44: =L44 -> 7141.6 | N44: =M44 -> 7141.6 | O44: =N44 -> 7141.6 | P44: =O44 -> 7141.6 | Q44: =P44 -> 7141.6
D45: Total Liabilities | F45: ₹ MM | H45: =SUM(H40:H44) -> 39612.5 | I45: =SUM(I40:I44) -> 52218.6 | J45: =SUM(J40:J44) -> 43216.5 | K45: =SUM(K40:K44) -> 48605 | L45: =SUM(L40:L44) -> 52511.8 | M45: =SUM(M40:M44) -> 51698.917 | N45: =SUM(N40:N44) -> 53221.395 | O45: =SUM(O40:O44) -> 54987.492 | ... Q45: =SUM(Q40:Q44) -> 44234.736
...

Sheet Scenarios
A1: =Sheet1!B1 -> Alkem Laboratories Ltd
A2: Scenarios
C4: Scenarios | E4: Growth(%) | G4: =Model!M2 -> 2026 | H4: =Model!N2 -> 2027 | I4: =Model!O2 -> 2028 | J4: =Model!P2 -> 2029 | K4: =Model!Q2 -> 2030
D5: Base Case | E5: =AVERAGE(Model!I107:L107) -> 0.10146596 | G5: =E5 -> 0.10146596 | H5: =G5*(1-$E$8) -> 0.081172772 | I5: =H5*(1-$E$8) -> 0.064938217 | J5: =I5*(1-$E$8) -> 0.051950574 | K5: =J5*(1-$E$8) -> 0.041560459
D6: Bull Case | E6: =MAX(Model!I107:L107) -> 0.19956887 | G6: =E6 -> 0.19956887 | H6: =G6*(1-$E$8) -> 0.15965509 | I6: =H6*(1-$E$8) -> 0.12772407 | J6: =I6*(1-$E$8) -> 0.10217926 | K6: =J6*(1-$E$8) -> 0.081743408
D7: Bear Case | E7: =MIN(Model!I107:L107) -> 0.023440941 | G7: =E7 -> 0.023440941 | H7: =G7*(1-$E$8) -> 0.018752753 | I7: =H7*(1-$E$8) -> 0.015002202 | J7: =I7*(1-$E$8) -> 0.012001762 | K7: =J7*(1-$E$8) -> 0.0096014096
D8: Annual Growth Tapering | E8: 0.2

Sheet Comps
A1: =Sheet1!B1 -> Alkem Laboratories Ltd
A2: Comps Valuation
E5: Market Data | L5: Fiancial Data | P5: Valuation
E6: Price | F6: Shares | G6: Market Cap | H6: Debt | I6: Cash | J6: EV | L6: Sales | M6: EBITDA | N6: Earning | P6: EV/Sales | Q6: EV/EBITDA | R6: P/E
D7: Company Name | E7: ₹/Share | F7: M | G7: ₹MM | I7: & Equivalents | J7: ₹MM | L7: ₹MM | M7: ₹MM | N7: ₹MM | P7: x | Q7: x | R7: x
D8: ='Comps Data'!B6 -> Zydus Lifesciences Limited | E8: ='Comps Data'!D6 -> 860.55 | F8: ='Comps Data'!E6 -> 1006.3 | G8: =E8*F8 -> 865971.46 | H8: ='Comps Data'!F6 -> 100496.74 | I8: ='Comps Data'!G6 -> 9068.66 | J8: =G8+H8-I8 -> 957399.54 | L8: ='Comps Data'!H6 -> 272090.33 | M8: ='Comps Data'!I6 -> 75899.23 | N8: ='Comps Data'!J6 -> 51503.52 | P8: =J8/L8 -> 3.5186827 | Q8: =J8/M8 -> 12.614088 | R8: =G8/N8 -> 16.813831
D9: ='Comps Data'!B7 -> Torrent Pharmaceuticals Limited | E9: ='Comps Data'!D7 -> 4213.95 | F9: ='Comps Data'!E7 -> 338.5 | G9: =E9*F9 -> 1426422.1 | H9: ='Comps Data'!F7 -> 29431.18 | I9: ='Comps Data'!G7 -> 6290.15 | J9: =G9+H9-I9 -> 1449563.1 | L9: ='Comps Data'!H7 -> 132889.71 | M9: ='Comps Data'!I7 -> 42788.13 | N9: ='Comps Data'!J7 -> 23697.73 | P9: =J9/L9 -> 10.908016 | Q9: =J9/M9 -> 33.877692 | R9: =G9/N9 -> 60.192351
D10: ='Comps Data'!B8 -> Dr. Reddy's Laboratories Limited | E10: ='Comps Data'!D8 -> 1252.55 | F10: ='Comps Data'!E8 -> 832.9 | G10: =E10*F10 -> 1043248.9 | H10: ='Comps Data'!F8 -> 70639.01 | I10: ='Comps Data'!G8 -> 19457.74 | J10: =G10+H10-I10 -> 1094430.2 | L10: ='Comps Data'!H8 -> 360673.8 | M10: ='Comps Data'!I8 -> 88424.95 | N10: ='Comps Data'!J8 -> 59015.67 | P10: =J10/L10 -> 3.0344044 | Q10: =J10/M10 -> 12.376938 | R10: =G10/N10 -> 17.67749
D11: ='Comps Data'!B9 -> Aurobindo Pharma Limited | E11: ='Comps Data'!D9 -> 1279.3 | F11: ='Comps Data'!E9 -> 580.8 | G11: =E11*F11 -> 743017.44 | H11: ='Comps Data'!F9 -> 81290.34 | I11: ='Comps Data'!G9 -> 61082.41 | J11: =G11+H11-I11 -> 763225.37 | L11: ='Comps Data'!H9 -> 346060 | M11: ='Comps Data'!I9 -> 69727.68 | N11: ='Comps Data'!J9 -> 36366.18 | P11: =J11/L11 -> 2.2054712 | Q11: =J11/M11 -> 10.945802 | R11: =G11/N11 -> 20.43155
D12: ='Comps Data'!B10 -> Glenmark Pharmaceuticals Limited | E12: ='Comps Data'!D10 -> 2081 | F12: ='Comps Data'!E10 -> 282.3 | G12: =E12*F12 -> 587466.3 | H12: ='Comps Data'!F10 -> 12767.18 | I12: ='Comps Data'!G10 -> 18379.81 | J12: =G12+H12-I12 -> 581853.67 | L12: ='Comps Data'!H10 -> 172182.69 | M12: ='Comps Data'!I10 -> 42027.44 | N12: ='Comps Data'!J10 -> 11108 | P12: =J12/L12 -> 3.3792809 | Q12: =J12/M12 -> 13.844614 | R12: =G12/N12 -> 52.886775
D13: ='Comps Data'!B11 -> Lupin Limited | E13: ='Comps Data'!D11 -> 2297.2 | F13: ='Comps Data'!E11 -> 458.2 | G13: =E13*F13 -> 1052577 | H13: ='Comps Data'!F11 -> 64838.29 | I13: ='Comps Data'!G11 -> 16931.79 | J13: =G13+H13-I13 -> 1100483.5 | L13: ='Comps Data'!H11 -> 272728.59 | M13: ='Comps Data'!I11 -> 71507.18 | N13: ='Comps Data'!J11 -> 48444.02 | P13: =J13/L13 -> 4.0350868 | Q13: =J13/M13 -> 15.389833 | R13: =G13/N13 -> 21.727698
D14: ='Comps Data'!B12 -> Mankind Pharma Limited | E14: ='Comps Data'!D12 -> 1922.45 | F14: ='Comps Data'!E12 -> 412.8 | G14: =E14*F14 -> 793587.36 | H14: ='Comps Data'!F12 -> 87278.26 | I14: ='Comps Data'!G12 -> 4468.08 | J14: =G14+H14-I14 -> 876397.54 | L14: ='Comps Data'!H12 -> 145112.62 | M14: ='Comps Data'!I12 -> 33718.33 | N14: ='Comps Data'!J12 -> 18557.18 | P14: =J14/L14 -> 6.0394302 | Q14: =J14/M14 -> 25.991724 | R14: =G14/N14 -> 42.764437
D16: Average | P16: =AVERAGE(P8:P14) -> 4.7314818 | Q16: =AVERAGE(Q8:Q14) -> 17.862956 | R16: =AVERAGE(R8:R14) -> 33.213447
D17: Median | P17: =MEDIAN(P8:P14) -> 3.5186827 | Q17: =MEDIAN(Q8:Q14) -> 13.844614 | R17: =MEDIAN(R8:R14) -> 21.727698
D19: Alkem Laboratories Ltd | E19: ='Comps Data'!D4 -> 5145.6 | F19: ='Comps Data'!E4 -> 119.6 | G19: =E19*F19 -> 615413.76 | H19: ='Comps Data'!F4 -> 24567.01 | I19: ='Comps Data'!G4 -> 3335.93 | J19: =G19+H19-I19 -> 636644.84 | L19: ='Comps Data'!H4 -> 148644.15 | M19: ='Comps Data'!I4 -> 29569.94 | N19: ='Comps Data'!J4 -> 24729.7 | P19: =J19/L19 -> 4.2830131 | Q19: =J19/M19 -> 21.530136 | R19: =G19/N19 -> 24.885614
D21: Metric | E21: Comps | F21: EV | G21: Net Debt | H21: Equity Value | I21: Shares | J21: Share Price
D22: EV/Revenue | E22: =P17 -> 3.5186827 | F22: =E22*L19 -> 523031.6 | G22: =H19-I19 -> 21231.08 | H22: =F22-G22 -> 501800.52 | I22: =F19 -> 119.6 | J22: =H22/I22 -> 4195.6566
D23: EV/EBITDA | E23: =Q17 -> 13.844614 | F23: =E23*M19 -> 409384.4 | G23: =G22 -> 21231.08 | H23: =F23-G23 -> 388153.32 | I23: =I22 -> 119.6 | J23: =H23/I23 -> 3245.4291
D24: P/E | E24: =R17 -> 21.727698 | F24: =H24+G24 -> 558550.54 | G24: =G23 -> 21231.08 | H24: =E24*N19 -> 537319.46 | I24: =I23 -> 119.6 | J24: =H24/I24 -> 4492.6376

Sheet Comps Data
B3: Company | C3: Ticker | D3: Stock Price | E3: Shares Outstanding Dil | F3: Total Debt | G3: Cash And Equivalents | H3: Total Revenues | I3: EBITDA | J3: Net Income | K3: Effective Tax Rate
B4: Alkem Laboratories Limited | C4: ALKEM | D4: 5145.6 | E4: 119.6 | F4: 24567.01 | G4: 3335.93 | H4: 148644.15 | I4: 29569.94 | J4: 24729.7 | K4: 0.148
B6: Zydus Lifesciences Limited | C6: ZYDUSLIFE | D6: 860.55 | E6: 1006.3 | F6: 100496.74 | G6: 9068.66 | H6: 272090.33 | I6: 75899.23 | J6: 51503.52 | K6: 0.253
B7: Torrent Pharmaceuticals Limited | C7: 500420 | D7: 4213.95 | E7: 338.5 | F7: 29431.18 | G7: 6290.15 | H7: 132889.71 | I7: 42788.13 | J7: 23697.73 | K7: 0.245
B8: Dr. Reddy's Laboratories Limited | C8: 500124 | D8: 1252.55 | E8: 832.9 | F8: 70639.01 | G8: 19457.74 | H8: 360673.8 | I8: 88424.95 | J8: 59015.67 | K8: 0.23
B9: Aurobindo Pharma Limited | C9: AUROPHARMA | D9: 1279.3 | E9: 580.8 | F9: 81290.34 | G9: 61082.41 | H9: 346060 | I9: 69727.68 | J9: 36366.18 | K9: 0.324
B10: Glenmark Pharmaceuticals Limited | C10: GLENMARK | D10: 2081 | E10: 282.3 | F10: 12767.18 | G10: 18379.81 | H10: 172182.69 | I10: 42027.44 | J10: 11108 | K10: 0.336
B11: Lupin Limited | C11: 500257 | D11: 2297.2 | E11: 458.2 | F11: 64838.29 | G11: 16931.79 | H11: 272728.59 | I11: 71507.18 | J11: 48444.02 | K11: 0.201
B12: Mankind Pharma Limited | C12: MANKIND | D12: 1922.45 | E12: 412.8 | F12: 87278.26 | G12: 4468.08 | H12: 145112.62 | I12: 33718.33 | J12: 18557.18 | K12: 0.174

Sheet Market Data
A1: =Sheet1!B1 -> Alkem Laboratories Ltd
A2: Equity Market Data
E4: Index
D5: Date | E5: Closing Price | G5: Index | H5: Nifty 50
D6: 46103 | E6: 22701.6 | G6: Years | H6: =YEARFRAC(D6,D527) -> 9.9861111
D7: 46096 | E7: 23114.5 | G7: Returns | H7: =_xlfn.RRI(H6,E527,E6) -> 0.11416173
D8: 46089 | E8: 23151.1
D9: 46082 | E9: 24450.45
D10: 46075 | E10: 25178.65
D11: 46068 | E11: 25571.25
D12: 46061 | E12: 25471.1
D13: 46054 | E13: 25693.7
D14: 46047 | E14: 25320.65
D15: 46040 | E15: 25048.65
D16: 46033 | E16: 25694.35
D17: 46026 | E17: 25683.3
D18: 46019 | E18: 26328.55
D19: 46012 | E19: 26042.3
... D527: 42456 | E527: 7713.05

Sheet WACC
A1: =Sheet1!B1 -> Alkem Laboratories Ltd
A2: Weighted-Average Cost of Capital(WACC)
A3: All Amounts in INR MM
A5: Comparable Companies Beta
D6: Equity | E6: Total | F6: Debt/ | G6: Debt/ | H6: Tax | I6: Levered | J6: Unlevered
B7: Name | D7: Value | E7: Debt | F7: Equity | G7: Capital | H7: Rate % | I7: Beta | J7: Beta
B8: =Comps!D8 -> Zydus Lifesciences Limited | D8: =Comps!G8 -> 865971.46 | E8: =Comps!H8 -> 100496.74 | F8: =E8/D8 -> 0.11605087 | G8: =E8/(D8+E8) -> 0.10398349 | H8: ='Comps Data'!K6 -> 0.253 | I8: 0.74 | J8: =I8/(1+F8*(1-H8)) -> 0.68096697
B9: =Comps!D9 -> Torrent Pharmaceuticals Limited | D9: =Comps!G9 -> 1426422.1 | E9: =Comps!H9 -> 29431.18 | F9: =E9/D9 -> 0.020632869 | G9: =E9/(D9+E9) -> 0.02021576 | H9: ='Comps Data'!K7 -> 0.245 | I9: 0.16 | J9: =I9/(1+F9*(1-H9)) -> 0.15754578
B10: =Comps!D10 -> Dr. Reddy's Laboratories Limited | D10: =Comps!G10 -> 1043248.9 | E10: =Comps!H10 -> 70639.01 | F10: =E10/D10 -> 0.067710601 | G10: =E10/(D10+E10) -> 0.063416624 | H10: ='Comps Data'!K8 -> 0.23 | I10: 0.12 | J10: =I10/(1+F10*(1-H10)) -> 0.11405357
B11: =Comps!D11 -> Aurobindo Pharma Limited | D11: =Comps!G11 -> 743017.44 | E11: =Comps!H11 -> 81290.34 | F11: =E11/D11 -> 0.1094057 | G11: =E11/(D11+E11) -> 0.09861649 | H11: ='Comps Data'!K9 -> 0.324 | I11: 0.06 | J11: =I11/(1+F11*(1-H11)) -> 0.055868094
B12: =Comps!D12 -> Glenmark Pharmaceuticals Limited | D12: =Comps!G12 -> 587466.3 | E12: =Comps!H12 -> 12767.18 | F12: =E12/D12 -> 0.021732617 | G12: =E12/(D12+E12) -> 0.021270356 | H12: ='Comps Data'!K10 -> 0.336 | I12: 0.29 | J12: =I12/(1+F12*(1-H12)) -> 0.2858747
B13: =Comps!D13 -> Lupin Limited | D13: =Comps!G13 -> 1052577 | E13: =Comps!H13 -> 64838.29 | F13: =E13/D13 -> 0.061599567 | G13: =E13/(D13+E13) -> 0.058025238 | H13: ='Comps Data'!K11 -> 0.201 | I13: 0.31 | J13: =I13/(1+F13*(1-H13)) -> 0.29545813
B14: =Comps!D14 -> Mankind Pharma Limited | D14: =Comps!G14 -> 793587.36 | E14: =Comps!H14 -> 87278.26 | F14: =E14/D14 -> 0.1099794 | G14: =E14/(D14+E14) -> 0.099082378 | H14: ='Comps Data'!K12 -> 0.174 | I14: 0.18 | J14: =I14/(1+F14*(1-H14)) -> 0.16501
B15: Average | F15: =AVERAGE(F8:F14) -> 0.072444517 | G15: =AVERAGE(G8:G14) -> 0.066372905 | H15: =AVERAGE(H8:H14) -> 0.25185714 | I15: =AVERAGE(I8:I14) -> 0.26571429 | J15: =AVERAGE(J8:J14) -> 0.25068246
B16: Median | F16: =MEDIAN(F8:F14) -> 0.067710601 | G16: =MEDIAN(G8:G14) -> 0.063416624 | H16: =MEDIAN(H8:H14) -> 0.245 | I16: =MEDIAN(I8:I14) -> 0.18 | J16: =MEDIAN(J8:J14) -> 0.16501
B18: Alkem Pharma | D18: =Comps!G19 -> 615413.76 | E18: =Comps!H19 -> 24567.01
B20: WACC Calculation
B22: Target capital Structure
B24: Proportion of Debt | J24: =G15 -> 0.066372905
B25: Proportion of Equity | J25: =1-J24 -> 0.93362709
B26: Current Capital Structure
B27: Market Cap | J27: =D18 -> 615413.76
B28: Total Debt | J28: =E18 -> 24567.01
B29: Debt/Equity | J29: =J28/J27 -> 0.039919501
B31: Cost of Debt
B32: Pre-Tax Cost of Debt | J32: =Model!M112 -> 0.058936422
B33: Tax Rate | J33: ='Comps Data'!K4 -> 0.148
B34: After Tax Cost of Capital | J34: =J32*(1-J33) -> 0.050213831
B36: Cost of Equity
B37: Risk Free Rate | J37: 0.0682
B38: Equity Market Return | J38: ='Market Data'!H7 -> 0.11416173
B39: Equity Risk Premium | J39: =J38-J37 -> 0.045961733
B40: Levered Equity Beta | J40: =J16*(1+J29*(1-J33)) -> 0.17062222
B41: Cost of Equity | J41: =J37+J39*J40 -> 0.076042093
B43: WACC | J43: =(J34*J24)+(J41*J25) -> 0.074327796

Sheet Beta
A1: =Sheet1!B1 -> Alkem Laboratories Ltd
A2: Company Beta
C4: Index | D4: % Change | E4: Stock | F4: % Change
B5: Date | C5: Close Price | D5: Monthly | E5: Close Price | F5: Monthly
B6: 46082 | C6: 23034.6 | E6: 5247.5
B7: 46054 | C7: 25178.65 | D7: =C7/C6-1 -> 0.093079541 | E7: 5639.5 | F7: =E7/E6-1 -> 0.074702239 | I7: Beta1 | J7: =SLOPE(F7:F77,D7:D77) -> 0.76991993
B8: 46023 | C8: 25320.65 | D8: =C8/C7-1 -> 0.0056396987 | E8: 5677.5 | F8: =E8/E7-1 -> 0.006738186 | I8: Beta2 | J8: =J29 -> 0.76991993
B9: 45992 | C9: 26129.6 | D9: =C9/C8-1 -> 0.031948232 | E9: 5506.5 | F9: =E9/E8-1 -> -0.03011889
B10: 45962 | C10: 26202.95 | D10: =C10/C9-1 -> 0.0028071612 | E10: 5685 | F10: =E10/E9-1 -> 0.032416235
B11: 45931 | C11: 25722.1 | D11: =C11/C10-1 -> -0.018350987 | E11: 5506.5 | F11: =E11/E10-1 -> -0.031398417
B12: 45901 | C12: 24611.1 | D12: =C12/C11-1 -> -0.04319243 | E12: 5425 | F12: =E12/E11-1 -> -0.01480069 | I12: SUMMARY OUTPUT
B13: 45870 | C13: 24426.85 | D13: =C13/C12-1 -> -0.0074864594 | E13: 5303.5 | F13: =E13/E12-1 -> -0.022396313
B14: 45839 | C14: 24768.35 | D14: =C14/C13-1 -> 0.013980517 | E14: 5031.1 | F14: =E14/E13-1 -> -0.051362308 | I14: Regression Statistics
B15: 45809 | C15: 25517.05 | D15: =C15/C14-1 -> 0.030228094 | E15: 4939 | F15: =E15/E14-1 -> -0.018306136 | I15: Multiple R | J15: 0.45475661
B16: 45778 | C16: 24750.7 | D16: =C16/C15-1 -> -0.03003286 | E16: 5098.5 | F16: =E16/E15-1 -> 0.032293987 | I16: R Square | J16: 0.20680357
B17: 45748 | C17: 24334.2 | D17: =C17/C16-1 -> -0.016827807 | E17: 5116 | F17: =E17/E16-1 -> 0.0034323821 | I17: Adjusted R Square | J17: 0.19530797
B18: 45717 | C18: 23519.35 | D18: =C18/C17-1 -> -0.033485794 | E18: 4881.7 | F18: =E18/E17-1 -> -0.045797498 | I18: Standard Error | J18: 0.059588525
B19: 45689 | C19: 22124.7 | D19: =C19/C18-1 -> -0.059297982 | E19: 4646.2 | F19: =E19/E18-1 -> -0.048241391 | I19: Observations | J19: 71
B20: 45658 | C20: 23508.4 | D20: =C20/C19-1 -> 0.062540961 | E20: 5063.05 | F20: =E20/E19-1 -> 0.08971848
B21: 45627 | C21: 23644.8 | D21: =C21/C20-1 -> 0.0058021813 | E21: 5633.9 | F21: =E21/E20-1 -> 0.11274824 | I21: ANOVA
B22: 45597 | C22: 24131.1 | D22: =C22/C21-1 -> 0.02056689 | E22: 5642.45 | F22: =E22/E21-1 -> 0.0015175988 | J22: df | K22: SS | L22: MS | M22: F | N22: Significance F
B23: 45566 | C23: 24205.35 | D23: =C23/C22-1 -> 0.0030769422 | E23: 5779.25 | F23: =E23/E22-1 -> 0.024244787 | I23: Regression | J23: 1 | K23: 0.06387805 | L23: 0.06387805 | M23: 17.989802 | N23: 6.7736876e-05
B24: 45536 | C24: 25810.85 | D24: =C24/C23-1 -> 0.066328312 | E24: 6052.8 | F24: =E24/E23-1 -> 0.047333131 | I24: Residual | J24: 69 | K24: 0.24500467 | L24: 0.0035507924
B25: 45505 | C25: 25235.9 | D25: =C25/C24-1 -> -0.022275516 | E25: 6170.35 | F25: =E25/E24-1 -> 0.019420764 | I25: Total | J25: 70 | K25: 0.30888272
B26: 45474 | C26: 24951.15 | D26: =C26/C25-1 -> -0.011283529 | E26: 5309.5 | F26: =E26/E25-1 -> -0.13951397
B27: 45444 | C27: 24010.6 | D27: =C27/C26-1 -> -0.037695657 | E27: 4991.35 | F27: =E27/E26-1 -> -0.059920897 | J27: Coefficients | K27: Standard Error | L27: t Stat | M27: P-value | N27: Lower 95% | O27: Upper 95% | P27: Lower 95.0% | Q27: Upper 95.0%
B28: 45413 | C28: 22530.7 | D28: =C28/C27-1 -> -0.061635278 | E28: 4810.45 | F28: =E28/E27-1 -> -0.0362427 | I28: Intercept | J28: 0.00082461465 | K28: 0.0073539095 | L28: 0.11213283 | M28: 0.91104367 | N28: -0.013846033 | O28: 0.015495263 | P28: -0.013846033 | Q28: 0.015495263
B29: 45383 | C29: 22604.85 | D29: =C29/C28-1 -> 0.0032910651 | E29: 4833.05 | F29: =E29/E28-1 -> 0.0046981052 | I29: X Variable 1 | J29: 0.76991993 | K29: 0.1815233 | L29: 4.2414386 | M29: 6.7736876e-05 | N29: 0.40779086 | O29: 1.132049 | P29: 0.40779086 | Q29: 1.132049
B30: 45352 | C30: 22326.9 | D30: =C30/C29-1 -> -0.012296034 | E30: 4942 | F30: =E30/E29-1 -> 0.022542701
B31: 45323 | C31: 21982.8 | D31: =C31/C30-1 -> -0.015411902 | E31: 5127.35 | F31: =E31/E30-1 -> 0.037505059
B32: 45292 | C32: 21725.7 | D32: =C32/C31-1 -> -0.011695507 | E32: 4996.05 | F32: =E32/E31-1 -> -0.02560777
B33: 45261 | C33: 21731.4 | D33: =C33/C32-1 -> 0.00026236209 | E33: 5202.6 | F33: =E33/E32-1 -> 0.041342661
B34: 45231 | C34: 20133.15 | D34: =C34/C33-1 -> -0.073545653 | E34: 4723.55 | F34: =E34/E33-1 -> -0.092078961
B35: 45200 | C35: 19079.6 | D35: =C35/C34-1 -> -0.052329119 | E35: 3721.85 | F35: =E35/E34-1 -> -0.21206508
B36: 45170 | C36: 19638.3 | D36: =C36/C35-1 -> 0.029282585 | E36: 3605.9 | F36: =E36/E35-1 -> -0.031153862
B37: 45139 | C37: 19253.8 | D37: =C37/C36-1 -> -0.019579088 | E37: 3642.85 | F37: =E37/E36-1 -> 0.010247095
B38: 45108 | C38: 19753.8 | D38: =C38/C37-1 -> 0.0259689 | E38: 3978.75 | F38: =E38/E37-1 -> 0.092208024
B39: 45078 | C39: 19189.05 | D39: =C39/C38-1 -> -0.028589436 | E39: 3512.85 | F39: =E39/E38-1 -> -0.11709708
B40: 45047 | C40: 18534.4 | D40: =C40/C39-1 -> -0.034115811 | E40: 3359.6 | F40: =E40/E39-1 -> -0.043625546
B41: 45017 | C41: 18065 | D41: =C41/C40-1 -> -0.025325881 | E41: 3509.9 | F41: =E41/E40-1 -> 0.044737469
...

Sheet DCF Model
A1: =Sheet1!B1 -> Alkem Laboratories Ltd
A2: DCF Model
B5: DCF Model
B7: Assumptions
B8: Transaction Date | D8: 46077
B9: Fiscal Year End | D9: 46112
B10: Tax Rate | D10: =WACC!J33 -> 0.148
B11: EV/EBITDA | D11: =Comps!Q17 -> 13.844614
B12: Perpetual Growth Rate | D12: 0.06
B13: Discount Rate | D13: =WACC!J43 -> 0.074327796
B14: Shares O/S | D14: =119565000/10^6 -> 119.565
B15: Current Price | D15: 5287
B19: Discounted Cash Flow | E19: Entry | F19: =YEAR(D9) -> 2026 | G19: =F19+1 -> 2027 | H19: =G19+1 -> 2028 | I19: =H19+1 -> 2029 | J19: Exit | L19: Trminal value
B20: Date | E20: =D8 -> 46077 | F20: =DATE(YEAR($E$20)+F21,MONTH($D$9),DAY($D$9)) -> 46112 | G20: =DATE(YEAR($E$20)+G21,MONTH($D$9),DAY($D$9)) -> 46477 | H20: =DATE(YEAR($E$20)+H21,MONTH($D$9),DAY($D$9)) -> 46843 | I20: =DATE(YEAR($E$20)+I21,MONTH($D$9),DAY($D$9)) -> 47208 | J20: =I20 -> 47208 | L20: Ev/EBITDA | N20: =(I24+I27)*D11 -> 437682.48
B21: Time Periods | F21: 0 | G21: 1 | H21: 2 | I21: 3 | L21: Perp.Growth | N21: =I30*(1+D12)/(D13-D12) -> 1788125.5
B22: Year Frac. | F22: =YEARFRAC(E20,F20) -> 0.10277778 | G22: =YEARFRAC(F20,G20) -> 1 | H22: =YEARFRAC(G20,H20) -> 1 | I22: =YEARFRAC(H20,I20) -> 1 | J22: 1 | L22: Average | N22: =AVERAGE(N20:N21) -> 1112904
B24: EBIT | F24: =Model!M14 -> 22830.034 | G24: =Model!N14 -> 23720.307 | H24: =Model!O14 -> 25212.014 | I24: =Model!P14 -> 28431.362
B25: Less:Cash Taxes | F25: =-F24*$D$10 -> -3378.845 | G25: =-G24*$D$10 -> -3510.6055 | H25: =-H24*$D$10 -> -3731.3781 | I25: =-I24*$D$10 -> -4207.8415
B26: NOPAT | F26: =SUM(F24:F25) -> 19451.189 | G26: =SUM(G24:G25) -> 20209.702 | H26: =SUM(H24:H25) -> 21480.636 | I26: =SUM(I24:I25) -> 24223.52
B27: Add: Depreciation & Amortzation | F27: =Model!M57 -> 3500.672 | G27: =Model!N57 -> 3407.6778 | H27: =Model!O57 -> 3321.6489 | I27: =Model!P57 -> 3182.5565
B28: Less : Capex | F28: =-Model!M94 -> -2709.7698 | G28: =-Model!N94 -> -2164.8063 | H28: =-Model!O94 -> -1712.5105 | I28: =-Model!P94 -> -1344.1757
B29: Less:Change in NWC | F29: =Model!M90 -> -7368.2203 | G29: =Model!N90 -> -2657.2456 | H29: =Model!O90 -> -924.57123 | I29: =Model!P90 -> -1892.1859
B30: Unleverd FCFF | F30: =SUM(F26:F29) -> 12873.871 | G30: =SUM(G26:G29) -> 18795.328 | H30: =SUM(H26:H29) -> 22165.204 | I30: =SUM(I26:I29) -> 24169.715 | J30: =N22 -> 1112904
B32: Transaction FCFF | E32: 0 | F32: =F30*F22 -> 1323.1479 | G32: =G30*G22 -> 18795.328 | H32: =H30*H22 -> 22165.204 | I32: =I30*I22 -> 24169.715 | J32: =J30*J22 -> 1112904
B38: Intrinsic Value | F38: Market value | J38: Rate of Return
B39: EV | D39: =XNPV(D13,E32:J32,E20:J20) -> 948315.18 | F39: Market Cap | H39: =D15*D14 -> 632140.16 | J39: Current Price | L39: =D15 -> 5287
B40: Add: Cash & Equivalent | D40: =Model!L25+Model!L26+Model!L34 -> 61430.9 | F40: Add: Debt | H40: =-D41 -> 13809 | J40: Target Price | L40: =D45 -> 8292.138
B41: Less: Debt | D41: =-Model!L101 -> -13809 | F41: Add: Non-Controlling Int | H41: =-D42 -> 4487.6 | J41: TP Uside | L41: =L40/L39-1 -> 0.56840136
B42: Less: Non-Controlling Int | D42: =-Model!L50 -> -4487.6 | F42: Less: Cash | H42: =-D40 -> -61430.9
B43: Equity Value | D43: =SUM(D39:D42) -> 991449.48 | F43: Enterprise Value | H43: =SUM(H39:H42) -> 589005.85
B45: Equity Value/Share | D45: =D43/D14 -> 8292.138 | F45: Equity Value/Share | H45: =H39/D14 -> 5287

Sheet Sensitivity Analysis
A1: =Sheet1!B1 -> Alkem Laboratories Ltd
A2: Sensitivity Analysis
B5: Sensitivity Analysis
F7: Sensitivity Analysis - Intrinsic Value(Rs./Share)
G9: Exit Multiple
F10: ='DCF Model'!D45 -> 8292.138 | G10: 3 | H10: 7 | I10: 13.84 | J10: 15 | K10: 17
F11: 0.05 | G11: 8292.138 | H11: 8292.138 | I11: 8292.138 | J11: 8292.138 | K11: 8292.138 | R11: ='DCF Model'!D11 -> 13.844614
F12: 0.06 | G12: 8292.138 | H12: 8292.138 | I12: 8292.138 | J12: 8292.138 | K12: 8292.138 | R12: ='DCF Model'!D13 -> 0.074327796
E13: Discount rate | F13: 0.0743 | G13: 8292.138 | H13: 8292.138 | I13: 8292.138 | J13: 8292.138 | K13: 8292.138
F14: 0.09 | G14: 8292.138 | H14: 8292.138 | I14: 8292.138 | J14: 8292.138 | K14: 8292.138
F15: 0.11 | G15: 8292.138 | H15: 8292.138 | I15: 8292.138 | J15: 8292.138 | K15: 8292.138
